Workbook

Sheet База кормів
A1: 🏷️ ОСНОВНА ІНФОРМАЦІЯ | J1: 📊 АНАЛІТИЧНИЙ СКЛАД (as fed) | O1: 📊 СКЛАД (на суху речовину DM) | S1: 🧪 ІНГРЕДІЄНТИ / БІЛОК | W1: 💊 ВІТАМІНИ | AF1: ⚗️ МІНЕРАЛИ (форма + засвоєння) | BC1: 📝 ІНШЕ
A2: ID | B2: Бренд | C2: Лінійка | D2: Назва корму | E2: Тип | F2: Для кого | G2: Призначення | H2: ккал/кг | I2: URL джерела | J2: Білок % (as fed) | K2: Жир % (as fed) | L2: Клітковина % (as fed) | M2: Зола % (as fed) | N2: Вологість % | O2: Білок % (DM) | P2: Жир % (DM) | Q2: Клітковина % (DM) | R2: Зола % (DM) | S2: Повний склад | T2: Джерело білка 1 | U2: Джерело білка 2 | V2: Джерело білка 3 | W2: Віт A (МО/кг) | X2: Віт D3 (МО/кг) | Y2: Віт E (мг/кг) | Z2: Віт C (мг/кг) | AA2: Таурин (мг/кг) | AB2: B1 (мг/кг) | AC2: B2 (мг/кг) | AD2: B6 (мг/кг) | AE2: B12 (мкг/кг) | AF2: Zn загальний (мг/кг) | AG2: Zn форма 1 | AH2: Zn % форми 1 | AI2: Zn форма 2 | AJ2: Zn % форми 2 | AK2: Zn засвоєння % | AL2: Fe загальний (мг/кг) | AM2: Fe форма 1 | AN2: Fe % форми 1 | AO2: Fe форма 2 | AP2: Fe % форми 2 | AQ2: Fe засвоєння % | AR2: Cu загальний (мг/кг) | AS2: Cu форма 1 | AT2: Cu % форми 1 | AU2: Cu засвоєння % | AV2: Mn загальний (мг/кг) | AW2: Mn форма 1 | AX2: Mn % форми 1 | AY2: Mn засвоєння % | AZ2: Se (мг/кг) | BA2: Se форма | BB2: Se засвоєння % | BC2: I (мг/кг) | BD2: Примітки
A3: rc_sterilised37_dry_cat | B3: Royal Canin | C3: Sterilised | D3: Sterilised 37 (сухий) | E3: сухий | F3: кіт | G3: стерилізовані | H3: 363 | I3: https://www.royalcanin.com/ua/cats/products/retail-products/sterilised-37-dry | J3: 37 | K3: 12 | L3: 6.2 | M3: 8.2 | N3: 5.5 | O3: =IF(J3="","",ROUND(J3/(1-N3/100),1)) | P3: =IF(K3="","",ROUND(K3/(1-N3/100),1)) | Q3: =IF(L3="","",ROUND(L3/(1-N3/100),1)) | R3: =IF(M3="","",ROUND(M3/(1-N3/100),1)) | S3: Дегідратовані протеїни м'яса птиці, кукурудза, ізолят рослинних протеїнів (L.I.P.), рослинна клітковина, тваринні жири, гідролізат білків тваринного походження, рис, пшениця, буряковий жом, кукурудзяний глютен, дріжджі та їх частки, мінеральні речовини, риб'ячий жир, фруктоолігосахариди, соєва олія | T3: дегідратовані протеїни м'яса птиці | U3: ізолят рослинних протеїнів (L.I.P.) | V3: гідролізат білків тваринного походження | W3: 19000 | X3: 1000 | AF3: 122 | AG3: оксид цинку / сульфат цинку | AK3: =IF(AF3="","",IF(AH3="",IFERROR(VLOOKUP(AG3,Довідник_мінералів!$A:$B,2,0),"-"),ROUND(IFERROR(VLOOKUP(AG3,Довідник_мінералів!$A:$B,2,0),0)*AH3/100+IFERROR(VLOOKUP(AI3,Довідник_мінералів!$A:$B,2,0),0)*AJ3/100,0))) | AL3: 31 | AM3: сульфат заліза(II) | AQ3: =IF(AL3="","",IF(AN3="",IFERROR(VLOOKUP(AM3,Довідник_мінералів!$A:$B,2,0),"-"),ROUND(IFERROR(VLOOKUP(AM3,Довідник_мінералів!$A:$B,2,0),0)*AN3/100+IFERROR(VLOOKUP(AO3,Довідник_мінералів!$A:$B,2,0),0)*AP3/100,0))) | AR3: 10 | AS3: сульфат міді | AU3: =IF(AR3="","",IFERROR(VLOOKUP(AS3,Довідник_мінералів!$A:$B,2,0),"-")) | AV3: 41 | AW3: оксид марганцю | AY3: =IF(AV3="","",IFERROR(VLOOKUP(AW3,Довідник_мінералів!$A:$B,2,0),"-")) | AZ3: 0.05 | BA3: селеніт натрію | BB3: =IF(SE3="","",IFERROR(VLOOKUP(BA3,Довідник_мінералів!$A:$B,2,0),"-")) | BC3: 3.1 | BD3: L-карнітин: 100 мг; амоній хлорид: 5 г; вологість: 5.5%
A4: rc_kitten_dry_cat | B4: Royal Canin | C4: Kitten | D4: Kitten (сухий) | E4: сухий | F4: кіт | G4: кошенята 4-12 міс | H4: 400 | I4: https://www.royalcanin.com/ua/cats/products/retail-products/kitten-dry | J4: 36 | K4: 18 | L4: 2.3 | M4: 7.8 | N4: 5.5 | O4: =IF(J4="","",ROUND(J4/(1-N4/100),1)) | P4: =IF(K4="","",ROUND(K4/(1-N4/100),1)) | Q4: =IF(L4="","",ROUND(L4/(1-N4/100),1)) | R4: =IF(M4="","",ROUND(M4/(1-N4/100),1)) | S4: Дегідратовані протеїни м'яса птиці, рис, пшеничний глютен (L.I.P.), тваринні жири, кукурудзяне борошно, гідролізат протеїнів тваринного походження, пшеничне борошно, кукурудзяний глютен, дріжджові продукти, буряковий жом, рослинна клітковина, мінеральні речовини, соєва олія, риб'ячий жир, оболонка та насіння подорожника, фруктоолігосахариди, гідролізат дріжджів (МОС та бета-глюкани), олія водоростей Шізохітріум (ДГК), борошно чорнобривців прямостоячих | T4: дегідратовані протеїни м'яса птиці | U4: пшеничний глютен (L.I.P.) | V4: гідролізат протеїнів тваринного походження | W4: 21000 | X4: 800 | Y4: 600 | AF4: 126 | AG4: оксид цинку / сульфат цинку | AK4: =IF(AF4="","",IF(AH4="",IFERROR(VLOOKUP(AG4,Довідник_мінералів!$A:$B,2,0),"-"),ROUND(IFERROR(VLOOKUP(AG4,Довідник_мінералів!$A:$B,2,0),0)*AH4/100+IFERROR(VLOOKUP(AI4,Довідник_мінералів!$A:$B,2,0),0)*AJ4/100,0))) | AL4: 32 | AM4: сульфат заліза(II) | AQ4: =IF(AL4="","",IF(AN4="",IFERROR(VLOOKUP(AM4,Довідник_мінералів!$A:$B,2,0),"-"),ROUND(IFERROR(VLOOKUP(AM4,Довідник_мінералів!$A:$B,2,0),0)*AN4/100+IFERROR(VLOOKUP(AO4,Довідник_мінералів!$A:$B,2,0),0)*AP4/100,0))) | AR4: 10 | AS4: сульфат міді | AU4: =IF(AR4="","",IFERROR(VLOOKUP(AS4,Довідник_мінералів!$A:$B,2,0),"-")) | AV4: 42 | AW4: оксид марганцю | AY4: =IF(AV4="","",IFERROR(VLOOKUP(AW4,Довідник_мінералів!$A:$B,2,0),"-")) | AZ4: 0.05 | BA4: селеніт натрію | BB4: =IF(SE4="","",IFERROR(VLOOKUP(BA4,Довідник_мінералів!$A:$B,2,0),"-")) | BC4: 3.2 | BD4: Містить ДГК з водоростей; вологість 5.5%; кальцій 1.2%
A5: rc_fit32_dry_cat | B5: Royal Canin | C5: Fit | D5: Fit 32 (сухий) | E5: сухий | F5: кіт | G5: здоровий дорослий | H5: 389 | I5: https://www.royalcanin.com/ua/cats/products/retail-products/fit-32-dry | J5: 32 | K5: 15 | L5: 4.6 | M5: 7.2 | N5: 5.5 | O5: =IF(J5="","",ROUND(J5/(1-N5/100),1)) | P5: =IF(K5="","",ROUND(K5/(1-N5/100),1)) | Q5: =IF(L5="","",ROUND(L5/(1-N5/100),1)) | R5: =IF(M5="","",ROUND(M5/(1-N5/100),1)) | S5: Дегідратовані протеїни м'яса птиці, рис, пшениця, кукурудза, тваринні жири, дегідратовані протеїни свинини, рослинна клітковина, пшеничне борошно, гідролізат білків тваринного походження, кукурудзяний глютен, дріжджі та їх частки, буряковий жом, соєва олія, риб'ячий жир, мінеральні речовини, оболонка та насіння подорожника, гідролізат дріжджів (МОС), екстракт чорнобривців (лютеїн) | T5: дегідратовані протеїни м'яса птиці | U5: дегідратовані протеїни свинини | V5: гідролізат білків тваринного походження | W5: 13000 | X5: 700 | AF5: 136 | AG5: оксид цинку / сульфат цинку | AK5: =IF(AF5="","",IF(AH5="",IFERROR(VLOOKUP(AG5,Довідник_мінералів!$A:$B,2,0),"-"),ROUND(IFERROR(VLOOKUP(AG5,Довідник_мінералів!$A:$B,2,0),0)*AH5/100+IFERROR(VLOOKUP(AI5,Довідник_мінералів!$A:$B,2,0),0)*AJ5/100,0))) | AL5: 35 | AM5: сульфат заліза(II) | AQ5: =IF(AL5="","",IF(AN5="",IFERROR(VLOOKUP(AM5,Довідник_мінералів!$A:$B,2,0),"-"),ROUND(IFERROR(VLOOKUP(AM5,Довідник_мінералів!$A:$B,2,0),0)*AN5/100+IFERROR(VLOOKUP(AO5,Довідник_мінералів!$A:$B,2,0),0)*AP5/100,0))) | AR5: 11 | AS5: сульфат міді | AU5: =IF(AR5="","",IFERROR(VLOOKUP(AS5,Довідник_мінералів!$A:$B,2,0),"-")) | AV5: 45 | AW5: оксид марганцю | AY5: =IF(AV5="","",IFERROR(VLOOKUP(AW5,Довідник_мінералів!$A:$B,2,0),"-")) | AZ5: 0.09 | BA5: селеніт натрію | BB5: =IF(SE5="","",IFERROR(VLOOKUP(BA5,Довідник_мінералів!$A:$B,2,0),"-")) | BC5: 3.5 | BD5: амоній хлорид: 5 г; для котів з помірною активністю
A6: rc_indoor_dry_cat | B6: Royal Canin | C6: Indoor | D6: Indoor (сухий) | E6: сухий | F6: кіт | G6: здоровий дорослий indoor | H6: 352 | I6: https://www.royalcanin.com/ua/cats/products/retail-products/indoor-dry | J6: 27 | K6: 13 | L6: 4 | M6: 7.3 | N6: 5.5 | O6: =IF(J6="","",ROUND(J6/(1-N6/100),1)) | P6: =IF(K6="","",ROUND(K6/(1-N6/100),1)) | Q6: =IF(L6="","",ROUND(L6/(1-N6/100),1)) | R6: =IF(M6="","",ROUND(M6/(1-N6/100),1)) | S6: Дегідратовані протеїни м'яса птиці, рис, пшениця, кукурудза, рослинна клітковина, тваринні жири, гідролізат білків тваринного походження, кукурудзяний глютен, дріжджі та їх частки, буряковий жом, мінеральні речовини, соєва олія, риб'ячий жир, оболонка та насіння подорожника, гідролізат дріжджів (МОС), екстракт чорнобривців (лютеїн) | T6: дегідратовані протеїни м'яса птиці | U6: гідролізат білків тваринного походження | V6: кукурудзяний глютен | X6: 700 | AF6: 164 | AG6: оксид цинку / сульфат цинку | AK6: =IF(AF6="","",IF(AH6="",IFERROR(VLOOKUP(AG6,Довідник_мінералів!$A:$B,2,0),"-"),ROUND(IFERROR(VLOOKUP(AG6,Довідник_мінералів!$A:$B,2,0),0)*AH6/100+IFERROR(VLOOKUP(AI6,Довідник_мінералів!$A:$B,2,0),0)*AJ6/100,0))) | AL6: 42 | AM6: сульфат заліза(II) | AQ6: =IF(AL6="","",IF(AN6="",IFERROR(VLOOKUP(AM6,Довідник_мінералів!$A:$B,2,0),"-"),ROUND(IFERROR(VLOOKUP(AM6,Довідник_мінералів!$A:$B,2,0),0)*AN6/100+IFERROR(VLOOKUP(AO6,Довідник_мінералів!$A:$B,2,0),0)*AP6/100,0))) | AR6: 13 | AS6: сульфат міді | AU6: =IF(AR6="","",IFERROR(VLOOKUP(AS6,Довідник_мінералів!$A:$B,2,0),"-")) | AV6: 55 | AW6: оксид марганцю | AY6: =IF(AV6="","",IFERROR(VLOOKUP(AW6,Довідник_мінералів!$A:$B,2,0),"-")) | AZ6: 0.09 | BA6: селеніт натрію | BB6: =IF(SE6="","",IFERROR(VLOOKUP(BA6,Довідник_мінералів!$A:$B,2,0),"-")) | BC6: 4.2 | BD6: Для котів що живуть у приміщенні; виведення грудочок шерсті
A7: rc_urinary_care_dry_cat | B7: Royal Canin | C7: Urinary Care | D7: Urinary Care (сухий) | E7: сухий | F7: кіт | G7: МКХ профілактика | H7: 376 | I7: https://www.royalcanin.com/ua/cats/products/retail-products/urinary-care-1800 | J7: 33 | K7: 13 | L7: 5 | M7: 6.6 | N7: 5.5 | O7: =IF(J7="","",ROUND(J7/(1-N7/100),1)) | P7: =IF(K7="","",ROUND(K7/(1-N7/100),1)) | Q7: =IF(L7="","",ROUND(L7/(1-N7/100),1)) | R7: =IF(M7="","",ROUND(M7/(1-N7/100),1)) | S7: Дегідратовані протеїни м'яса птиці (L.I.P.), рис, кукурудза, пшениця, тваринні жири, гідролізат білків тваринного походження, кукурудзяний глютен, дріжджі та їх частки, буряковий жом, рослинна клітковина, мінеральні речовини, риб'ячий жир, соєва олія, оболонка та насіння подорожника, фруктоолігосахариди, гідролізат дріжджів (МОС), екстракт чорнобривців (лютеїн) | T7: дегідратовані протеїни м'яса птиці (L.I.P.) | U7: гідролізат білків тваринного походження | V7: кукурудзяний глютен | W7: 20500 | X7: 700 | AF7: 109 | AG7: оксид цинку / сульфат цинку | AK7: =IF(AF7="","",IF(AH7="",IFERROR(VLOOKUP(AG7,Довідник_мінералів!$A:$B,2,0),"-"),ROUND(IFERROR(VLOOKUP(AG7,Довідник_мінералів!$A:$B,2,0),0)*AH7/100+IFERROR(VLOOKUP(AI7,Довідник_мінералів!$A:$B,2,0),0)*AJ7/100,0))) | AL7: 40 | AM7: сульфат заліза(II) | AQ7: =IF(AL7="","",IF(AN7="",IFERROR(VLOOKUP(AM7,Довідник_мінералів!$A:$B,2,0),"-"),ROUND(IFERROR(VLOOKUP(AM7,Довідник_мінералів!$A:$B,2,0),0)*AN7/100+IFERROR(VLOOKUP(AO7,Довідник_мінералів!$A:$B,2,0),0)*AP7/100,0))) | AR7: 12 | AS7: сульфат міді | AU7: =IF(AR7="","",IFERROR(VLOOKUP(AS7,Довідник_мінералів!$A:$B,2,0),"-")) | AV7: 52 | AW7: оксид марганцю | AY7: =IF(AV7="","",IFERROR(VLOOKUP(AW7,Довідник_мінералів!$A:$B,2,0),"-")) | AZ7: 0.07 | BA7: селеніт натрію | BB7: =IF(SE7="","",IFERROR(VLOOKUP(BA7,Довідник_мінералів!$A:$B,2,0),"-")) | BC7: 4 | BD7: pH сечі 6.0-6.5; S/O index; профілактика струвітів та оксалатів
A8: rc_hair_skin_dry_cat | B8: Royal Canin | C8: Hair & Skin | D8: Hair & Skin Care (сухий) | E8: сухий | F8: кіт | G8: шкіра та шерсть | H8: 415 | I8: https://www.royalcanin.com/ua/cats/products/retail-products/hair-skin-care-dry | J8: 33 | K8: 22 | L8: 5 | M8: 6.9 | N8: 5.5 | O8: =IF(J8="","",ROUND(J8/(1-N8/100),1)) | P8: =IF(K8="","",ROUND(K8/(1-N8/100),1)) | Q8: =IF(L8="","",ROUND(L8/(1-N8/100),1)) | R8: =IF(M8="","",ROUND(M8/(1-N8/100),1)) | S8: Дегідратований білок з м'яса свійської птиці (L.I.P.), тваринні жири, пшеничний глютен (L.I.P.), рис, рослинне волокно, кукурудза, гідролізовані тваринні білки, пшениця, дріжджові продукти, кукурудзяне борошно, олія огірковика, мінеральні речовини | T8: дегідратований білок з м'яса свійської птиці (L.I.P.) | U8: пшеничний глютен (L.I.P.) | V8: гідролізовані тваринні білки | W8: 26000 | X8: 700 | AF8: 102 | AG8: оксид цинку / сульфат цинку | AK8: =IF(AF8="","",IF(AH8="",IFERROR(VLOOKUP(AG8,Довідник_мінералів!$A:$B,2,0),"-"),ROUND(IFERROR(VLOOKUP(AG8,Довідник_мінералів!$A:$B,2,0),0)*AH8/100+IFERROR(VLOOKUP(AI8,Довідник_мінералів!$A:$B,2,0),0)*AJ8/100,0))) | AL8: 37 | AM8: сульфат заліза(II) | AQ8: =IF(AL8="","",IF(AN8="",IFERROR(VLOOKUP(AM8,Довідник_мінералів!$A:$B,2,0),"-"),ROUND(IFERROR(VLOOKUP(AM8,Довідник_мінералів!$A:$B,2,0),0)*AN8/100+IFERROR(VLOOKUP(AO8,Довідник_мінералів!$A:$B,2,0),0)*AP8/100,0))) | AR8: 11 | AS8: сульфат міді | AU8: =IF(AR8="","",IFERROR(VLOOKUP(AS8,Довідник_мінералів!$A:$B,2,0),"-")) | AV8: 48 | AW8: оксид марганцю | AY8: =IF(AV8="","",IFERROR(VLOOKUP(AW8,Довідник_мінералів!$A:$B,2,0),"-")) | AZ8: 0.06 | BA8: селеніт натрію | BB8: =IF(SE8="","",IFERROR(VLOOKUP(BA8,Довідник_мінералів!$A:$B,2,0),"-")) | BC8: 3.7 | BD8: Омега-3: 11.5 г/кг; Омега-6: 52.9 г/кг; олія огірковика (GLA)
A9: rc_sensible33_dry_cat | B9: Royal Canin | C9: Sensible | D9: Sensible 33 (сухий) | E9: сухий | F9: кіт | G9: чутливе травлення | H9: 357 | I9: https://www.royalcanin.com/ua/cats/products/retail-products/sensible-33-2521 | J9: 33 | K9: 22 | L9: 1.6 | M9: 7.4 | N9: 5.5 | O9: =IF(J9="","",ROUND(J9/(1-N9/100),1)) | P9: =IF(K9="","",ROUND(K9/(1-N9/100),1)) | Q9: =IF(L9="","",ROUND(L9/(1-N9/100),1)) | R9: =IF(M9="","",ROUND(M9/(1-N9/100),1)) | S9: Дегідратовані протеїни м'яса птиці (L.I.P.), рис, кукурудза, тваринні жири, гідролізат білків тваринного походження, дріжджі та їх частки, пшениця, буряковий жом, кукурудзяний глютен, рослинна клітковина, мінеральні речовини, риб'ячий жир, соєва олія, оболонка та насіння подорожника, фруктоолігосахариди, гідролізат дріжджів (МОС), екстракт чорнобривців (лютеїн) | T9: дегідратовані протеїни м'яса птиці (L.I.P.) | U9: рис | V9: гідролізат білків тваринного походження | W9: 18500 | X9: 1000 | AF9: 150 | AG9: оксид цинку / сульфат цинку | AK9: =IF(AF9="","",IF(AH9="",IFERROR(VLOOKUP(AG9,Довідник_мінералів!$A:$B,2,0),"-"),ROUND(IFERROR(VLOOKUP(AG9,Довідник_мінералів!$A:$B,2,0),0)*AH9/100+IFERROR(VLOOKUP(AI9,Довідник_мінералів!$A:$B,2,0),0)*AJ9/100,0))) | AL9: 38 | AM9: сульфат заліза(II) | AQ9: =IF(AL9="","",IF(AN9="",IFERROR(VLOOKUP(AM9,Довідник_мінералів!$A:$B,2,0),"-"),ROUND(IFERROR(VLOOKUP(AM9,Довідник_мінералів!$A:$B,2,0),0)*AN9/100+IFERROR(VLOOKUP(AO9,Довідник_мінералів!$A:$B,2,0),0)*AP9/100,0))) | AR9: 12 | AS9: сульфат міді | AU9: =IF(AR9="","",IFERROR(VLOOKUP(AS9,Довідник_мінералів!$A:$B,2,0),"-")) | AV9: 50 | AW9: оксид марганцю | AY9: =IF(AV9="","",IFERROR(VLOOKUP(AW9,Довідник_мінералів!$A:$B,2,0),"-")) | AZ9: 0.1 | BA9: селеніт натрію | BB9: =IF(SE9="","",IFERROR(VLOOKUP(BA9,Довідник_мінералів!$A:$B,2,0),"-")) | BC9: 3.8 | BD9: Рис як основне джерело вуглеводів; L.I.P. білки; pH сечі 6.0-6.5
A10: rc_savour_exigent_dry_cat | B10: Royal Canin | C10: Exigent | D10: Savour Exigent (сухий) | E10: сухий | F10: кіт | G10: здоровий дорослий вибагливий | H10: 396 | I10: https://www.royalcanin.com/ua/cats/products/retail-products/savour-exigent-dry | J10: 33 | K10: 16 | L10: 3.1 | M10: 7.2 | N10: 5.5 | O10: =IF(J10="","",ROUND(J10/(1-N10/100),1)) | P10: =IF(K10="","",ROUND(K10/(1-N10/100),1)) | Q10: =IF(L10="","",ROUND(L10/(1-N10/100),1)) | R10: =IF(M10="","",ROUND(M10/(1-N10/100),1)) | S10: Два типи крокет різної текстури: 1) Дегідратовані протеїни м'яса птиці (L.I.P.), рис, пшениця, кукурудза, тваринні жири, гідролізат білків тваринного походження, кукурудзяний глютен, дріжджі та їх частки, буряковий жом 2) Дегідратовані протеїни м'яса птиці (L.I.P.), кукурудза, рис, тваринні жири, кукурудзяний глютен, рослинна клітковина, мінеральні речовини | T10: дегідратовані протеїни м'яса птиці (L.I.P.) | U10: гідролізат білків тваринного походження | V10: кукурудзяний глютен | W10: 14500 | X10: 800 | AF10: 143 | AG10: оксид цинку / сульфат цинку | AK10: =IF(AF10="","",IF(AH10="",IFERROR(VLOOKUP(AG10,Довідник_мінералів!$A:$B,2,0),"-"),ROUND(IFERROR(VLOOKUP(AG10,Довідник_мінералів!$A:$B,2,0),0)*AH10/100+IFERROR(VLOOKUP(AI10,Довідник_мінералів!$A:$B,2,0),0)*AJ10/100,0))) | AL10: 37 | AM10: сульфат заліза(II) | AQ10: =IF(AL10="","",IF(AN10="",IFERROR(VLOOKUP(AM10,Довідник_мінералів!$A:$B,2,0),"-"),ROUND(IFERROR(VLOOKUP(AM10,Довідник_мінералів!$A:$B,2,0),0)*AN10/100+IFERROR(VLOOKUP(AO10,Довідник_мінералів!$A:$B,2,0),0)*AP10/100,0))) | AR10: 11 | AS10: сульфат міді | AU10: =IF(AR10="","",IFERROR(VLOOKUP(AS10,Довідник_мінералів!$A:$B,2,0),"-")) | AV10: 48 | AW10: оксид марганцю | AY10: =IF(AV10="","",IFERROR(VLOOKUP(AW10,Довідник_мінералів!$A:$B,2,0),"-")) | AZ10: 0.08 | BA10: селеніт натрію | BB10: =IF(SE10="","",IFERROR(VLOOKUP(BA10,Довідник_мінералів!$A:$B,2,0),"-")) | BC10: 3.7 | BD10: Два типи крокет: аромат+текстура; амоній хлорид 5 г
A11: rc_sterilised7plus_dry_cat | B11: Royal Canin | C11: Sterilised | D11: Sterilised 7+ (сухий) | E11: сухий | F11: кіт | G11: стерилізовані похилий вік 7-12 років | H11: 341 | I11: https://www.royalcanin.com/ua/cats/products/retail-products/sterilised-7-dry | J11: 34 | K11: 12 | L11: 9.2 | M11: 7.5 | N11: 5.5 | O11: =IF(J11="","",ROUND(J11/(1-N11/100),1)) | P11: =IF(K11="","",ROUND(K11/(1-N11/100),1)) | Q11: =IF(L11="","",ROUND(L11/(1-N11/100),1)) | R11: =IF(M11="","",ROUND(M11/(1-N11/100),1)) | S11: Дегідратовані протеїни м'яса птиці (L.I.P.), ізолят рослинних протеїнів (L.I.P.), кукурудза, рослинна клітковина, пшениця, кукурудзяний глютен, тваринні жири, гідролізат білків тваринного походження, рис, мінеральні речовини, буряковий жом, дріжджі та їх частки, риб'ячий жир, соєва олія, фруктоолігосахариди, оболонка та насіння подорожника, гідролізат із панцира ракоподібних (глюкозамін), екстракт чорнобривців (лютеїн), хрящовий гідролізат (хондроїтин) | T11: дегідратовані протеїни м'яса птиці (L.I.P.) | U11: ізолят рослинних протеїнів (L.I.P.) | V11: гідролізат білків тваринного походження | W11: 17000 | X11: 900 | Z11: 180 | AF11: 136 | AG11: оксид цинку / сульфат цинку | AK11: =IF(AF11="","",IF(AH11="",IFERROR(VLOOKUP(AG11,Довідник_мінералів!$A:$B,2,0),"-"),ROUND(IFERROR(VLOOKUP(AG11,Довідник_мінералів!$A:$B,2,0),0)*AH11/100+IFERROR(VLOOKUP(AI11,Довідник_мінералів!$A:$B,2,0),0)*AJ11/100,0))) | AL11: 35 | AM11: сульфат заліза(II) | AQ11: =IF(AL11="","",IF(AN11="",IFERROR(VLOOKUP(AM11,Довідник_мінералів!$A:$B,2,0),"-"),ROUND(IFERROR(VLOOKUP(AM11,Довідник_мінералів!$A:$B,2,0),0)*AN11/100+IFERROR(VLOOKUP(AO11,Довідник_мінералів!$A:$B,2,0),0)*AP11/100,0))) | AR11: 11 | AS11: сульфат міді | AU11: =IF(AR11="","",IFERROR(VLOOKUP(AS11,Довідник_мінералів!$A:$B,2,0),"-")) | AV11: 45 | AW11: оксид марганцю | AY11: =IF(AV11="","",IFERROR(VLOOKUP(AW11,Довідник_мінералів!$A:$B,2,0),"-")) | AZ11: 0.06 | BA11: селеніт натрію | BB11: =IF(SE11="","",IFERROR(VLOOKUP(BA11,Довідник_мінералів!$A:$B,2,0),"-")) | BC11: 3.5 | BD11: Фосфор 0.73%; EPA/DHA 3.1 г/кг; глюкозамін+хондроїтин; екстракт чаю (поліфеноли)
A12: rc_ageing12_dry_cat | B12: Royal Canin | C12: Sterilised Ageing | D12: Sterilised Ageing 12+ (сухий) | E12: сухий | F12: кіт | G12: стерилізовані похилий вік 12+ років | I12: https://www.royalcanin.com/ua/cats/products/retail-products/sterilised-ageing-12-dry | J12: 30 | K12: 15 | L12: 4.9 | M12: 5.4 | N12: 5.5 | O12: =IF(J12="","",ROUND(J12/(1-N12/100),1)) | P12: =IF(K12="","",ROUND(K12/(1-N12/100),1)) | Q12: =IF(L12="","",ROUND(L12/(1-N12/100),1)) | R12: =IF(M12="","",ROUND(M12/(1-N12/100),1)) | S12: Кукурудза, ізолят рослинних протеїнів (L.I.P.), кукурудзяне борошно, дегідратовані протеїни м'яса птиці, пшениця, кукурудзяний глютен, тваринні жири, рослинна клітковина, гідролізат білків тваринного походження, екстракт цикорію, мінеральні речовини, риб'ячий жир, соєва олія, дріжджі та їх частки, томат (лікопен), фруктоолігосахариди, оболонка та насіння подорожника, гідролізат дріжджів (МОС), гідролізат панцира ракоподібних (глюкозамін), олія огірочника, екстракт чорнобривців (лютеїн), хрящовий гідролізат (хондроїтин) | T12: ізолят рослинних протеїнів (L.I.P.) | U12: дегідратовані протеїни м'яса птиці | V12: гідролізат білків тваринного походження | W12: 19000 | X12: 700 | AF12: 154 | AG12: оксид цинку / сульфат цинку | AK12: =IF(AF12="","",IF(AH12="",IFERROR(VLOOKUP(AG12,Довідник_мінералів!$A:$B,2,0),"-"),ROUND(IFERROR(VLOOKUP(AG12,Довідник_мінералів!$A:$B,2,0),0)*AH12/100+IFERROR(VLOOKUP(AI12,Довідник_мінералів!$A:$B,2,0),0)*AJ12/100,0))) | AL12: 40 | AM12: сульфат заліза(II) | AQ12: =IF(AL12="","",IF(AN12="",IFERROR(VLOOKUP(AM12,Довідник_мінералів!$A:$B,2,0),"-"),ROUND(IFERROR(VLOOKUP(AM12,Довідник_мінералів!$A:$B,2,0),0)*AN12/100+IFERROR(VLOOKUP(AO12,Довідник_мінералів!$A:$B,2,0),0)*AP12/100,0))) | AR12: 12 | AS12: сульфат міді | AU12: =IF(AR12="","",IFERROR(VLOOKUP(AS12,Довідник_мінералів!$A:$B,2,0),"-")) | AV12: 52 | AW12: оксид марганцю | AY12: =IF(AV12="","",IFERROR(VLOOKUP(AW12,Довідник_мінералів!$A:$B,2,0),"-")) | AZ12: 0.07 | BA12: селеніт натрію | BB12: =IF(SE12="","",IFERROR(VLOOKUP(BA12,Довідник_мінералів!$A:$B,2,0),"-")) | BC12: 4 | BD12: Фосфор 0.6%; омега-3 10.9 г/кг; лікопен 6.5 мг/кг; антиоксидантний комплекс
A13: rc_sterilised_wet_gravy_cat | B13: Royal Canin | C13: Sterilised | D13: Sterilised (вологий, соус) | E13: вологий | F13: кіт | G13: стерилізовані | H13: 85 | I13: https://www.royalcanin.com/ua/cats/products/retail-products/sterilised-gravy-wet | J13: 8.9 | K13: 2.6 | L13: 1.4 | M13: 1.5 | N13: 81 | O13: =IF(J13="","",ROUND(J13/(1-N13/100),1)) | P13: =IF(K13="","",ROUND(K13/(1-N13/100),1)) | Q13: =IF(L13="","",ROUND(L13/(1-N13/100),1)) | R13: =IF(M13="","",ROUND(M13/(1-N13/100),1)) | S13: М'ясо та субпродукти тваринного походження, злакові, субпродукти рослинного походження, мінеральні речовини, дріжджі | T13: м'ясо та субпродукти тваринного походження | U13: злакові | V13: субпродукти рослинного походження | X13: 80 | AF13: 9 | AG13: оксид цинку / сульфат цинку | AK13: =IF(AF13="","",IF(AH13="",IFERROR(VLOOKUP(AG13,Довідник_мінералів!$A:$B,2,0),"-"),ROUND(IFERROR(VLOOKUP(AG13,Довідник_мінералів!$A:$B,2,0),0)*AH13/100+IFERROR(VLOOKUP(AI13,Довідник_мінералів!$A:$B,2,0),0)*AJ13/100,0))) | AL13: 3 | AM13: сульфат заліза(II) | AQ13: =IF(AL13="","",IF(AN13="",IFERROR(VLOOKUP(AM13,Довідник_мінералів!$A:$B,2,0),"-"),ROUND(IFERROR(VLOOKUP(AM13,Довідник_мінералів!$A:$B,2,0),0)*AN13/100+IFERROR(VLOOKUP(AO13,Довідник_мінералів!$A:$B,2,0),0)*AP13/100,0))) | AR13: 2.5 | AS13: сульфат міді | AU13: =IF(AR13="","",IFERROR(VLOOKUP(AS13,Довідник_мінералів!$A:$B,2,0),"-")) | AV13: 0.9 | AW13: оксид марганцю | AY13: =IF(AV13="","",IFERROR(VLOOKUP(AW13,Довідник_мінералів!$A:$B,2,0),"-")) | BB13: =IF(SE13="","",IFERROR(VLOOKUP(BA13,Довідник_мінералів!$A:$B,2,0),"-")) | BC13: 0.31 | BD13: вологість 81%; кальцій, фосфор не вказані
A14: rc_kitten_loaf_wet_cat | B14: Royal Canin | C14: Kitten | D14: Kitten Loaf (вологий, паштет) | E14: вологий | F14: кіт | G14: кошенята 4-12 міс | I14: https://www.royalcanin.com/ua/cats/products/retail-products/kitten-loaf-wet | J14: 12.3 | K14: 4.3 | L14: 1 | M14: 2 | N14: 78 | O14: =IF(J14="","",ROUND(J14/(1-N14/100),1)) | P14: =IF(K14="","",ROUND(K14/(1-N14/100),1)) | Q14: =IF(L14="","",ROUND(L14/(1-N14/100),1)) | R14: =IF(M14="","",ROUND(M14/(1-N14/100),1)) | S14: М'ясо та м'ясні субпродукти, злакові, екстракти рослинних протеїнів, субпродукти рослинного походження, мінеральні речовини, вуглеводи, дріжджі, олії та жири | T14: м'ясо та м'ясні субпродукти | U14: екстракти рослинних протеїнів | V14: злакові | X14: 195 | AF14: 9 | AG14: оксид цинку / сульфат цинку | AK14: =IF(AF14="","",IF(AH14="",IFERROR(VLOOKUP(AG14,Довідник_мінералів!$A:$B,2,0),"-"),ROUND(IFERROR(VLOOKUP(AG14,Довідник_мінералів!$A:$B,2,0),0)*AH14/100+IFERROR(VLOOKUP(AI14,Довідник_мінералів!$A:$B,2,0),0)*AJ14/100,0))) | AL14: 2.8 | AM14: сульфат заліза(II) | AQ14: =IF(AL14="","",IF(AN14="",IFERROR(VLOOKUP(AM14,Довідник_мінералів!$A:$B,2,0),"-"),ROUND(IFERROR(VLOOKUP(AM14,Довідник_мінералів!$A:$B,2,0),0)*AN14/100+IFERROR(VLOOKUP(AO14,Довідник_мінералів!$A:$B,2,0),0)*AP14/100,0))) | AR14: 3.4 | AS14: сульфат міді | AU14: =IF(AR14="","",IFERROR(VLOOKUP(AS14,Довідник_мінералів!$A:$B,2,0),"-")) | AV14: 0.8 | AW14: оксид марганцю | AY14: =IF(AV14="","",IFERROR(VLOOKUP(AW14,Довідник_мінералів!$A:$B,2,0),"-")) | BB14: =IF(SE14="","",IFERROR(VLOOKUP(BA14,Довідник_мінералів!$A:$B,2,0),"-")) | BC14: 0.43 | BD14: Паштет для кошенят 4-12 міс; текстура адаптована для молочних зубів
A15: rc_kitten_gravy_wet_cat | B15: Royal Canin | C15: Kitten | D15: Kitten Instinctive (вологий, соус) | E15: вологий | F15: кіт | G15: кошенята 4-12 міс | I15: https://www.royalcanin.com/ua/cats/products/retail-products/kitten-instinctive-gravy-wet | J15: 12 | K15: 4 | L15: 0.7 | M15: 1.7 | N15: 78.2 | O15: =IF(J15="","",ROUND(J15/(1-N15/100),1)) | P15: =IF(K15="","",ROUND(K15/(1-N15/100),1)) | Q15: =IF(L15="","",ROUND(L15/(1-N15/100),1)) | R15: =IF(M15="","",ROUND(M15/(1-N15/100),1)) | S15: М'ясо та субпродукти тваринного походження, екстракти рослинних протеїнів, злакові, субпродукти рослинного походження, мінеральні речовини, олії та жири, дріжджі | T15: м'ясо та субпродукти тваринного походження | U15: екстракти рослинних протеїнів | V15: злакові | AK15: =IF(AF15="","",IF(AH15="",IFERROR(VLOOKUP(AG15,Довідник_мінералів!$A:$B,2,0),"-"),ROUND(IFERROR(VLOOKUP(AG15,Довідник_мінералів!$A:$B,2,0),0)*AH15/100+IFERROR(VLOOKUP(AI15,Довідник_мінералів!$A:$B,2,0),0)*AJ15/100,0))) | AQ15: =IF(AL15="","",IF(AN15="",IFERROR(VLOOKUP(AM15,Довідник_мінералів!$A:$B,2,0),"-"),ROUND(IFERROR(VLOOKUP(AM15,Довідник_мінералів!$A:$B,2,0),0)*AN15/100+IFERROR(VLOOKUP(AO15,Довідник_мінералів!$A:$B,2,0),0)*AP15/100,0))) | AU15: =IF(AR15="","",IFERROR(VLOOKUP(AS15,Довідник_мінералів!$A:$B,2,0),"-")) | AY15: =IF(AV15="","",IFERROR(VLOOKUP(AW15,Довідник_мінералів!$A:$B,2,0),"-")) | BB15: =IF(SE15="","",IFERROR(VLOOKUP(BA15,Довідник_мінералів!$A:$B,2,0),"-")) | BD15: Шматочки у соусі; Ca 0.25%, P 0.21%, Mg 0.02%
A16: rc_mother_babycat_mousse_cat | B16: Royal Canin | C16: Mother & Babycat | D16: Mother & Babycat Ultra Soft Mousse | E16: вологий | F16: кіт | G16: вагітні/годуючі + кошенята до 4 міс | I16: https://www.royalcanin.com/ua/cats/products/retail-products/mother-babycat-ultra-soft-mousse-wet | J16: 10.5 | K16: 5.5 | L16: 0.8 | M16: 1.7 | N16: 78.7 | O16: =IF(J16="","",ROUND(J16/(1-N16/100),1)) | P16: =IF(K16="","",ROUND(K16/(1-N16/100),1)) | Q16: =IF(L16="","",ROUND(L16/(1-N16/100),1)) | R16: =IF(M16="","",ROUND(M16/(1-N16/100),1)) | S16: М'ясо та субпродукти тваринного походження, олії та жири, злакові, молоко та молочні продукти, субпродукти рослинного походження, мінеральні речовини, дріжджі | T16: м'ясо та субпродукти тваринного походження | U16: молоко та молочні продукти | V16: олії та жири | X16: 120 | AF16: 15 | AG16: оксид цинку / сульфат цинку | AK16: =IF(AF16="","",IF(AH16="",IFERROR(VLOOKUP(AG16,Довідник_мінералів!$A:$B,2,0),"-"),ROUND(IFERROR(VLOOKUP(AG16,Довідник_мінералів!$A:$B,2,0),0)*AH16/100+IFERROR(VLOOKUP(AI16,Довідник_мінералів!$A:$B,2,0),0)*AJ16/100,0))) | AL16: 5 | AM16: сульфат заліза(II) | AQ16: =IF(AL16="","",IF(AN16="",IFERROR(VLOOKUP(AM16,Довідник_мінералів!$A:$B,2,0),"-"),ROUND(IFERROR(VLOOKUP(AM16,Довідник_мінералів!$A:$B,2,0),0)*AN16/100+IFERROR(VLOOKUP(AO16,Довідник_мінералів!$A:$B,2,0),0)*AP16/100,0))) | AR16: 3.3 | AS16: сульфат міді | AU16: =IF(AR16="","",IFERROR(VLOOKUP(AS16,Довідник_мінералів!$A:$B,2,0),"-")) | AV16: 1.5 | AW16: оксид марганцю | AY16: =IF(AV16="","",IFERROR(VLOOKUP(AW16,Довідник_мінералів!$A:$B,2,0),"-")) | BB16: =IF(SE16="","",IFERROR(VLOOKUP(BA16,Довідник_мінералів!$A:$B,2,0),"-")) | BC16: 0.4 | BD16: Мус; містить молоко; ДГК для розвитку мозку; вологість 78.7%
A17: rc_babycat_instinctive_wet_cat | B17: Royal Canin | C17: Babycat | D17: Babycat Instinctive (вологий, мус) | E17: вологий | F17: кіт | G17: кошенята до 4 міс + вагітні/годуючі | I17: https://www.royalcanin.com/ua/cats/products/retail-products/babycat-instinctive-wet | J17: 10.5 | K17: 5.5 | L17: 0.9 | M17: 1.9 | N17: 79 | O17: =IF(J17="","",ROUND(J17/(1-N17/100),1)) | P17: =IF(K17="","",ROUND(K17/(1-N17/100),1)) | Q17: =IF(L17="","",ROUND(L17/(1-N17/100),1)) | R17: =IF(M17="","",ROUND(M17/(1-N17/100),1)) | S17: М'ясо і м'ясні субпродукти, злаки, масла і жири, субпродукти рослинного походження, молоко і молочні продукти, мінеральні речовини, дріжджі, вуглеводи | T17: м'ясо і м'ясні субпродукти | U17: молоко і молочні продукти | V17: масла і жири | X17: 130 | AF17: 15 | AG17: оксид цинку / сульфат цинку | AK17: =IF(AF17="","",IF(AH17="",IFERROR(VLOOKUP(AG17,Довідник_мінералів!$A:$B,2,0),"-"),ROUND(IFERROR(VLOOKUP(AG17,Довідник_мінералів!$A:$B,2,0),0)*AH17/100+IFERROR(VLOOKUP(AI17,Довідник_мінералів!$A:$B,2,0),0)*AJ17/100,0))) | AL17: 5 | AM17: сульфат заліза(II) | AQ17: =IF(AL17="","",IF(AN17="",IFERROR(VLOOKUP(AM17,Довідник_мінералів!$A:$B,2,0),"-"),ROUND(IFERROR(VLOOKUP(AM17,Довідник_мінералів!$A:$B,2,0),0)*AN17/100+IFERROR(VLOOKUP(AO17,Довідник_мінералів!$A:$B,2,0),0)*AP17/100,0))) | AR17: 3 | AS17: сульфат міді | AU17: =IF(AR17="","",IFERROR(VLOOKUP(AS17,Довідник_мінералів!$A:$B,2,0),"-")) | AV17: 1.5 | AW17: оксид марганцю | AY17: =IF(AV17="","",IFERROR(VLOOKUP(AW17,Довідник_мінералів!$A:$B,2,0),"-")) | BB17: =IF(SE17="","",IFERROR(VLOOKUP(BA17,Довідник_мінералів!$A:$B,2,0),"-")) | BC17: 0.37 | BD17: Мус для кошенят до 4 міс; містить молоко; вологість 79%
A18: rc_instinctive_gravy_wet_cat | B18: Royal Canin | C18: Instinctive | D18: Instinctive (вологий, соус) | E18: вологий | F18: кіт | G18: здоровий дорослий | I18: https://www.royalcanin.com/ua/cats/products/retail-products/instinctive-gravy-wet | J18: 12 | K18: 2.8 | L18: 0.9 | M18: 1.5 | N18: 79.5 | O18: =IF(J18="","",ROUND(J18/(1-N18/100),1)) | P18: =IF(K18="","",ROUND(K18/(1-N18/100),1)) | Q18: =IF(L18="","",ROUND(L18/(1-N18/100),1)) | R18: =IF(M18="","",ROUND(M18/(1-N18/100),1)) | S18: М'ясо та м'ясні субпродукти, риба та рибні субпродукти, екстракти рослинних протеїнів, злакові, субпродукти рослинного походження, мінеральні речовини, вуглеводи | T18: м'ясо та м'ясні субпродукти | U18: риба та рибні субпродукти | V18: екстракти рослинних протеїнів | X18: 35 | AF18: 9 | AG18: оксид цинку / сульфат цинку | AK18: =IF(AF18="","",IF(AH18="",IFERROR(VLOOKUP(AG18,Довідник_мінералів!$A:$B,2,0),"-"),ROUND(IFERROR(VLOOKUP(AG18,Довідник_мінералів!$A:$B,2,0),0)*AH18/100+IFERROR(VLOOKUP(AI18,Довідник_мінералів!$A:$B,2,0),0)*AJ18/100,0))) | AL18: 3 | AM18: сульфат заліза(II) | AQ18: =IF(AL18="","",IF(AN18="",IFERROR(VLOOKUP(AM18,Довідник_мінералів!$A:$B,2,0),"-"),ROUND(IFERROR(VLOOKUP(AM18,Довідник_мінералів!$A:$B,2,0),0)*AN18/100+IFERROR(VLOOKUP(AO18,Довідник_мінералів!$A:$B,2,0),0)*AP18/100,0))) | AR18: 2.8 | AS18: сульфат міді | AU18: =IF(AR18="","",IFERROR(VLOOKUP(AS18,Довідник_мінералів!$A:$B,2,0),"-")) | AV18: 0.9 | AW18: оксид марганцю | AY18: =IF(AV18="","",IFERROR(VLOOKUP(AW18,Довідник_мінералів!$A:$B,2,0),"-")) | BB18: =IF(SE18="","",IFERROR(VLOOKUP(BA18,Довідник_мінералів!$A:$B,2,0),"-")) | BC18: 0.35 | BD18: Шматочки у соусі; макронутрієнтний профіль для дорослих котів
A19: rc_instinctive_loaf_wet_cat | B19: Royal Canin | C19: Instinctive | D19: Instinctive Loaf (вологий, паштет) | E19: вологий | F19: кіт | G19: здоровий дорослий | I19: https://www.royalcanin.com/ua/cats/products/retail-products/instinctive-loaf-wet | J19: 12 | K19: 3.3 | L19: 1.3 | M19: 2 | O19: =IF(J19="","",ROUND(J19/(1-N19/100),1)) | P19: =IF(K19="","",ROUND(K19/(1-N19/100),1)) | Q19: =IF(L19="","",ROUND(L19/(1-N19/100),1)) | R19: =IF(M19="","",ROUND(M19/(1-N19/100),1)) | S19: М'ясо та м'ясні субпродукти, злакові, мінеральні речовини | T19: м'ясо та м'ясні субпродукти | U19: злакові | AK19: =IF(AF19="","",IF(AH19="",IFERROR(VLOOKUP(AG19,Довідник_мінералів!$A:$B,2,0),"-"),ROUND(IFERROR(VLOOKUP(AG19,Довідник_мінералів!$A:$B,2,0),0)*AH19/100+IFERROR(VLOOKUP(AI19,Довідник_мінералів!$A:$B,2,0),0)*AJ19/100,0))) | AQ19: =IF(AL19="","",IF(AN19="",IFERROR(VLOOKUP(AM19,Довідник_мінералів!$A:$B,2,0),"-"),ROUND(IFERROR(VLOOKUP(AM19,Довідник_мінералів!$A:$B,2,0),0)*AN19/100+IFERROR(VLOOKUP(AO19,Довідник_мінералів!$A:$B,2,0),0)*AP19/100,0))) | AU19: =IF(AR19="","",IFERROR(VLOOKUP(AS19,Довідник_мінералів!$A:$B,2,0),"-")) | AY19: =IF(AV19="","",IFERROR(VLOOKUP(AW19,Довідник_мінералів!$A:$B,2,0),"-")) | BB19: =IF(SE19="","",IFERROR(VLOOKUP(BA19,Довідник_мінералів!$A:$B,2,0),"-")) | BD19: Паштет; вологість не підтверджена — уточнити
A20: rc_hair_skin_wet_cat | B20: Royal Canin | C20: Hair & Skin | D20: Hair & Skin Care (вологий, желе) | E20: вологий | F20: кіт | G20: шкіра та шерсть | I20: https://www.royalcanin.com/ua/cats/products/retail-products/hair-skin-care-wet | J20: 10.5 | K20: 4 | L20: 1 | M20: 1.5 | N20: 81 | O20: =IF(J20="","",ROUND(J20/(1-N20/100),1)) | P20: =IF(K20="","",ROUND(K20/(1-N20/100),1)) | Q20: =IF(L20="","",ROUND(L20/(1-N20/100),1)) | R20: =IF(M20="","",ROUND(M20/(1-N20/100),1)) | S20: М'ясо та м'ясні субпродукти, риба та рибні субпродукти, злакові, екстракти рослинних протеїнів, олії та жири, субпродукти рослинного походження, мінеральні речовини, вуглеводи | T20: м'ясо та м'ясні субпродукти | U20: риба та рибні субпродукти | V20: екстракти рослинних протеїнів | X20: 100 | AF20: 21 | AG20: оксид цинку / сульфат цинку | AK20: =IF(AF20="","",IF(AH20="",IFERROR(VLOOKUP(AG20,Довідник_мінералів!$A:$B,2,0),"-"),ROUND(IFERROR(VLOOKUP(AG20,Довідник_мінералів!$A:$B,2,0),0)*AH20/100+IFERROR(VLOOKUP(AI20,Довідник_мінералів!$A:$B,2,0),0)*AJ20/100,0))) | AL20: 7 | AM20: сульфат заліза(II) | AQ20: =IF(AL20="","",IF(AN20="",IFERROR(VLOOKUP(AM20,Довідник_мінералів!$A:$B,2,0),"-"),ROUND(IFERROR(VLOOKUP(AM20,Довідник_мінералів!$A:$B,2,0),0)*AN20/100+IFERROR(VLOOKUP(AO20,Довідник_мінералів!$A:$B,2,0),0)*AP20/100,0))) | AR20: 1.8 | AS20: сульфат міді | AU20: =IF(AR20="","",IFERROR(VLOOKUP(AS20,Довідник_мінералів!$A:$B,2,0),"-")) | AV20: 2.1 | AW20: оксид марганцю | AY20: =IF(AV20="","",IFERROR(VLOOKUP(AW20,Довідник_мінералів!$A:$B,2,0),"-")) | BB20: =IF(SE20="","",IFERROR(VLOOKUP(BA20,Довідник_мінералів!$A:$B,2,0),"-")) | BC20: 0.23 | BD20: Омега-3: 0.16%; Омега-6: 0.94%; також є версія Intense Beauty
A21: rc_digest_sensitive_wet_cat | B21: Royal Canin | C21: Digest Sensitive | D21: Digest Sensitive (вологий, соус) | E21: вологий | F21: кіт | G21: чутливе травлення | I21: https://www.royalcanin.com/ua/cats/products/retail-products/digest-sensitive-wet | J21: 9.5 | K21: 4 | L21: 0.6 | M21: 1.7 | N21: 80.5 | O21: =IF(J21="","",ROUND(J21/(1-N21/100),1)) | P21: =IF(K21="","",ROUND(K21/(1-N21/100),1)) | Q21: =IF(L21="","",ROUND(L21/(1-N21/100),1)) | R21: =IF(M21="","",ROUND(M21/(1-N21/100),1)) | S21: М'ясо та м'ясні субпродукти, злакові, субпродукти рослинного походження, мінеральні речовини, риба та рибні субпродукти | T21: м'ясо та м'ясні субпродукти | U21: злакові | V21: субпродукти рослинного походження | X21: 200 | AF21: 11 | AG21: оксид цинку / сульфат цинку | AK21: =IF(AF21="","",IF(AH21="",IFERROR(VLOOKUP(AG21,Довідник_мінералів!$A:$B,2,0),"-"),ROUND(IFERROR(VLOOKUP(AG21,Довідник_мінералів!$A:$B,2,0),0)*AH21/100+IFERROR(VLOOKUP(AI21,Довідник_мінералів!$A:$B,2,0),0)*AJ21/100,0))) | AL21: 3.6 | AM21: сульфат заліза(II) | AQ21: =IF(AL21="","",IF(AN21="",IFERROR(VLOOKUP(AM21,Довідник_мінералів!$A:$B,2,0),"-"),ROUND(IFERROR(VLOOKUP(AM21,Довідник_мінералів!$A:$B,2,0),0)*AN21/100+IFERROR(VLOOKUP(AO21,Довідник_мінералів!$A:$B,2,0),0)*AP21/100,0))) | AR21: 2.8 | AS21: сульфат міді | AU21: =IF(AR21="","",IFERROR(VLOOKUP(AS21,Довідник_мінералів!$A:$B,2,0),"-")) | AV21: 1 | AW21: оксид марганцю | AY21: =IF(AV21="","",IFERROR(VLOOKUP(AW21,Довідник_мінералів!$A:$B,2,0),"-")) | BB21: =IF(SE21="","",IFERROR(VLOOKUP(BA21,Довідник_мінералів!$A:$B,2,0),"-")) | BC21: 0.35 | BD21: Шматочки у соусі; для котів з чутливим ШКТ
A22: rc_gi_dry_cat | B22: Royal Canin | C22: Gastrointestinal | D22: Gastrointestinal (сухий) | E22: сухий | F22: кіт | G22: ШКТ / панкреатит ремісія | I22: https://www.royalcanin.com/ua/cats/products/vet-products/gastro-intestinal-dry | J22: 32 | K22: 22 | L22: 4.9 | M22: 8.5 | O22: =IF(J22="","",ROUND(J22/(1-N22/100),1)) | P22: =IF(K22="","",ROUND(K22/(1-N22/100),1)) | Q22: =IF(L22="","",ROUND(L22/(1-N22/100),1)) | R22: =IF(M22="","",ROUND(M22/(1-N22/100),1)) | S22: Рис, дегідратовані протеїни м'яса птиці (L.I.P.), кукурудзяне борошно, тваринні жири, пшеничний глютен (L.I.P.), гідролізат білків тваринного походження, рослинна клітковина, мінеральні речовини, риб'ячий жир, соєва олія, фруктоолігосахариди, оболонка та насіння подорожника, гідролізат дріжджів (МОС та бета-глюкани) | T22: рис | U22: дегідратовані протеїни м'яса птиці (L.I.P.) | V22: пшеничний глютен (L.I.P.) | W22: 21500 | X22: 800 | AF22: 132 | AG22: оксид цинку / сульфат цинку | AK22: =IF(AF22="","",IF(AH22="",IFERROR(VLOOKUP(AG22,Довідник_мінералів!$A:$B,2,0),"-"),ROUND(IFERROR(VLOOKUP(AG22,Довідник_мінералів!$A:$B,2,0),0)*AH22/100+IFERROR(VLOOKUP(AI22,Довідник_мінералів!$A:$B,2,0),0)*AJ22/100,0))) | AL22: 41 | AM22: сульфат заліза(II) | AQ22: =IF(AL22="","",IF(AN22="",IFERROR(VLOOKUP(AM22,Довідник_мінералів!$A:$B,2,0),"-"),ROUND(IFERROR(VLOOKUP(AM22,Довідник_мінералів!$A:$B,2,0),0)*AN22/100+IFERROR(VLOOKUP(AO22,Довідник_мінералів!$A:$B,2,0),0)*AP22/100,0))) | AR22: 13 | AS22: сульфат міді | AU22: =IF(AR22="","",IFERROR(VLOOKUP(AS22,Довідник_мінералів!$A:$B,2,0),"-")) | AV22: 54 | AW22: оксид марганцю | AY22: =IF(AV22="","",IFERROR(VLOOKUP(AW22,Довідник_мінералів!$A:$B,2,0),"-")) | AZ22: 0.08 | BA22: селеніт натрію | BB22: =IF(SE22="","",IFERROR(VLOOKUP(BA22,Довідник_мінералів!$A:$B,2,0),"-")) | BC22: 4.1 | BD22: Омега-3: 0.93%; EPA/DHA: 0.33%; Na 0.6%; K 1%; S/O index
A23: rc_gi_mc_dry_cat | B23: Royal Canin | C23: Gastrointestinal | D23: Gastrointestinal Moderate Calorie (сухий) | E23: сухий | F23: кіт | G23: ШКТ зайва вага | I23: https://www.royalcanin.com/ua/cats/products/vet-products/gastro-intestinal-moderate-calorie-dry | J23: 34 | K23: 11 | L23: 7 | M23: 8.8 | O23: =IF(J23="","",ROUND(J23/(1-N23/100),1)) | P23: =IF(K23="","",ROUND(K23/(1-N23/100),1)) | Q23: =IF(L23="","",ROUND(L23/(1-N23/100),1)) | R23: =IF(M23="","",ROUND(M23/(1-N23/100),1)) | S23: Рис, дегідратовані протеїни м'яса птиці (L.I.P.), пшеничний глютен (L.I.P.), кукурудзяне борошно, рослинна клітковина, кукурудзяний глютен, гідролізат білків тваринного походження, мінеральні речовини, тваринні жири, риб'ячий жир, соєва олія, фруктоолігосахариди | T23: рис | U23: дегідратовані протеїни м'яса птиці (L.I.P.) | V23: пшеничний глютен (L.I.P.) | W23: 21500 | X23: 800 | AF23: 134 | AG23: оксид цинку / сульфат цинку | AK23: =IF(AF23="","",IF(AH23="",IFERROR(VLOOKUP(AG23,Довідник_мінералів!$A:$B,2,0),"-"),ROUND(IFERROR(VLOOKUP(AG23,Довідник_мінералів!$A:$B,2,0),0)*AH23/100+IFERROR(VLOOKUP(AI23,Довідник_мінералів!$A:$B,2,0),0)*AJ23/100,0))) | AL23: 35 | AM23: сульфат заліза(II) | AQ23: =IF(AL23="","",IF(AN23="",IFERROR(VLOOKUP(AM23,Довідник_мінералів!$A:$B,2,0),"-"),ROUND(IFERROR(VLOOKUP(AM23,Довідник_мінералів!$A:$B,2,0),0)*AN23/100+IFERROR(VLOOKUP(AO23,Довідник_мінералів!$A:$B,2,0),0)*AP23/100,0))) | AR23: 11 | AS23: сульфат міді | AU23: =IF(AR23="","",IFERROR(VLOOKUP(AS23,Довідник_мінералів!$A:$B,2,0),"-")) | AV23: 46 | AW23: оксид марганцю | AY23: =IF(AV23="","",IFERROR(VLOOKUP(AW23,Довідник_мінералів!$A:$B,2,0),"-")) | AZ23: 0.06 | BA23: селеніт натрію | BB23: =IF(SE23="","",IFERROR(VLOOKUP(BA23,Довідник_мінералів!$A:$B,2,0),"-")) | BC23: 3.5 | BD23: Ca 1%; P 0.9%; Na 1.2%; Mg 0.06%; таурин 0.22%; EPA/DHA 0.32%; L-карнітин 200 мг/кг
A24: rc_gi_mc_wet_cat | B24: Royal Canin | C24: Gastrointestinal | D24: Gastrointestinal Moderate Calorie (вологий) | E24: вологий | F24: кіт | G24: ШКТ зайва вага | I24: https://www.royalcanin.com/ua/cats/products/vet-products/gastro-intestinal-moderate-calorie-wet | J24: 7 | K24: 2.9 | L24: 0.9 | M24: 1.6 | N24: 82 | O24: =IF(J24="","",ROUND(J24/(1-N24/100),1)) | P24: =IF(K24="","",ROUND(K24/(1-N24/100),1)) | Q24: =IF(L24="","",ROUND(L24/(1-N24/100),1)) | R24: =IF(M24="","",ROUND(M24/(1-N24/100),1)) | S24: М'ясо та м'ясні субпродукти, злакові, субпродукти рослинного походження, мінеральні речовини, олії та жири, вуглеводи, дріжджі. Субпродукти птиці та свинини, кукурудзяне борошно, суміш кукурудзяного крохмалю | T24: субпродукти птиці та свинини | U24: злакові | X24: 240 | AF24: 7 | AG24: оксид цинку / сульфат цинку | AK24: =IF(AF24="","",IF(AH24="",IFERROR(VLOOKUP(AG24,Довідник_мінералів!$A:$B,2,0),"-"),ROUND(IFERROR(VLOOKUP(AG24,Довідник_мінералів!$A:$B,2,0),0)*AH24/100+IFERROR(VLOOKUP(AI24,Довідник_мінералів!$A:$B,2,0),0)*AJ24/100,0))) | AL24: 2 | AM24: сульфат заліза(II) | AQ24: =IF(AL24="","",IF(AN24="",IFERROR(VLOOKUP(AM24,Довідник_мінералів!$A:$B,2,0),"-"),ROUND(IFERROR(VLOOKUP(AM24,Довідник_мінералів!$A:$B,2,0),0)*AN24/100+IFERROR(VLOOKUP(AO24,Довідник_мінералів!$A:$B,2,0),0)*AP24/100,0))) | AR24: 2.4 | AS24: сульфат міді | AU24: =IF(AR24="","",IFERROR(VLOOKUP(AS24,Довідник_мінералів!$A:$B,2,0),"-")) | AV24: 0.7 | AW24: оксид марганцю | AY24: =IF(AV24="","",IFERROR(VLOOKUP(AW24,Довідник_мінералів!$A:$B,2,0),"-")) | BB24: =IF(SE24="","",IFERROR(VLOOKUP(BA24,Довідник_мінералів!$A:$B,2,0),"-")) | BC24: 0.3 | BD24: Na 0.11%; K 0.14%; Омега-3: 0.14%; Омега-6: 0.6%; S/O index
A25: rc_urinary_so_dry_cat | B25: Royal Canin | C25: Urinary S/O | D25: Urinary S/O (сухий) | E25: сухий | F25: кіт | G25: МКХ струвіти + оксалати | I25: https://www.royalcanin.com/ua/cats/products/vet-products/urinary-so-cat-dry | J25: 34.5 | K25: 15 | L25: 2.9 | M25: 8.9 | O25: =IF(J25="","",ROUND(J25/(1-N25/100),1)) | P25: =IF(K25="","",ROUND(K25/(1-N25/100),1)) | Q25: =IF(L25="","",ROUND(L25/(1-N25/100),1)) | R25: =IF(M25="","",ROUND(M25/(1-N25/100),1)) | S25: Рис, дегідратовані протеїни м'яса птиці (L.I.P.), пшеничний глютен (L.I.P.), кукурудзяне борошно, тваринні жири, гідролізат білків тваринного походження, рослинна клітковина, мінеральні речовини, риб'ячий жир, соєва олія, фруктоолігосахариди | T25: рис | U25: дегідратовані протеїни м'яса птиці (L.I.P.) | V25: пшеничний глютен (L.I.P.) | W25: 21500 | X25: 800 | AF25: 136 | AG25: оксид цинку / сульфат цинку | AK25: =IF(AF25="","",IF(AH25="",IFERROR(VLOOKUP(AG25,Довідник_мінералів!$A:$B,2,0),"-"),ROUND(IFERROR(VLOOKUP(AG25,Довідник_мінералів!$A:$B,2,0),0)*AH25/100+IFERROR(VLOOKUP(AI25,Довідник_мінералів!$A:$B,2,0),0)*AJ25/100,0))) | AL25: 37 | AM25: сульфат заліза(II) | AQ25: =IF(AL25="","",IF(AN25="",IFERROR(VLOOKUP(AM25,Довідник_мінералів!$A:$B,2,0),"-"),ROUND(IFERROR(VLOOKUP(AM25,Довідник_мінералів!$A:$B,2,0),0)*AN25/100+IFERROR(VLOOKUP(AO25,Довідник_мінералів!$A:$B,2,0),0)*AP25/100,0))) | AR25: 11 | AS25: сульфат міді | AU25: =IF(AR25="","",IFERROR(VLOOKUP(AS25,Довідник_мінералів!$A:$B,2,0),"-")) | AV25: 48 | AW25: оксид марганцю | AY25: =IF(AV25="","",IFERROR(VLOOKUP(AW25,Довідник_мінералів!$A:$B,2,0),"-")) | AZ25: 0.06 | BA25: селеніт натрію | BB25: =IF(SE25="","",IFERROR(VLOOKUP(BA25,Довідник_мінералів!$A:$B,2,0),"-")) | BC25: 3.7 | BD25: Ca 0.9%; P 0.9%; Na 1.3%; Mg 0.05%; таурин 0.23%; EPA/DHA 0.37%; підкислювачі сечі: Ca сульфат 1.25%, DL-метіонін 0.39%
A26: rc_urinary_so_mc_dry_cat | B26: Royal Canin | C26: Urinary S/O | D26: Urinary S/O Moderate Calorie (сухий) | E26: сухий | F26: кіт | G26: МКХ + зайва вага | I26: https://www.royalcanin.com/ua/cats/products/vet-products/urinary-so-moderate-calorie-dry | J26: 34 | K26: 11 | L26: 7 | M26: 8.8 | O26: =IF(J26="","",ROUND(J26/(1-N26/100),1)) | P26: =IF(K26="","",ROUND(K26/(1-N26/100),1)) | Q26: =IF(L26="","",ROUND(L26/(1-N26/100),1)) | R26: =IF(M26="","",ROUND(M26/(1-N26/100),1)) | S26: Рис, дегідратовані протеїни м'яса птиці, пшеничний глютен (L.I.P.), кукурудзяне борошно, рослинна клітковина, кукурудзяний глютен, гідролізат білків тваринного походження, мінеральні речовини, тваринні жири, риб'ячий жир, соєва олія, фруктоолігосахариди | T26: рис | U26: дегідратовані протеїни м'яса птиці | V26: пшеничний глютен (L.I.P.) | W26: 21500 | X26: 800 | AF26: 134 | AG26: оксид цинку / сульфат цинку | AK26: =IF(AF26="","",IF(AH26="",IFERROR(VLOOKUP(AG26,Довідник_мінералів!$A:$B,2,0),"-"),ROUND(IFERROR(VLOOKUP(AG26,Довідник_мінералів!$A:$B,2,0),0)*AH26/100+IFERROR(VLOOKUP(AI26,Довідник_мінералів!$A:$B,2,0),0)*AJ26/100,0))) | AL26: 35 | AM26: сульфат заліза(II) | AQ26: =IF(AL26="","",IF(AN26="",IFERROR(VLOOKUP(AM26,Довідник_мінералів!$A:$B,2,0),"-"),ROUND(IFERROR(VLOOKUP(AM26,Довідник_мінералів!$A:$B,2,0),0)*AN26/100+IFERROR(VLOOKUP(AO26,Довідник_мінералів!$A:$B,2,0),0)*AP26/100,0))) | AR26: 11 | AS26: сульфат міді | AU26: =IF(AR26="","",IFERROR(VLOOKUP(AS26,Довідник_мінералів!$A:$B,2,0),"-")) | AV26: 46 | AW26: оксид марганцю | AY26: =IF(AV26="","",IFERROR(VLOOKUP(AW26,Довідник_мінералів!$A:$B,2,0),"-")) | AZ26: 0.06 | BA26: селеніт натрію | BB26: =IF(SE26="","",IFERROR(VLOOKUP(BA26,Довідник_мінералів!$A:$B,2,0),"-")) | BC26: 3.5 | BD26: Ca 1%; P 0.9%; Na 1.2%; Mg 0.06%; таурин 0.22%; EPA/DHA 0.32%; L-карнітин 200 мг/кг
A27: rc_urinary_so_wet_cat | B27: Royal Canin | C27: Urinary S/O | D27: Urinary S/O (вологий) | E27: вологий | F27: кіт | G27: МКХ струвіти + оксалати | I27: https://www.royalcanin.com/ua/cats/products/vet-products/urinary-so-cat-wet | J27: 10 | K27: 3.5 | L27: 1 | M27: 1.8 | N27: 80 | O27: =IF(J27="","",ROUND(J27/(1-N27/100),1)) | P27: =IF(K27="","",ROUND(K27/(1-N27/100),1)) | Q27: =IF(L27="","",ROUND(L27/(1-N27/100),1)) | R27: =IF(M27="","",ROUND(M27/(1-N27/100),1)) | S27: М'ясо та м'ясні субпродукти, злакові, мінеральні речовини, олії та жири, субпродукти рослинного походження | T27: м'ясо та м'ясні субпродукти | U27: злакові | X27: 225 | AF27: 10 | AG27: оксид цинку / сульфат цинку | AK27: =IF(AF27="","",IF(AH27="",IFERROR(VLOOKUP(AG27,Довідник_мінералів!$A:$B,2,0),"-"),ROUND(IFERROR(VLOOKUP(AG27,Довідник_мінералів!$A:$B,2,0),0)*AH27/100+IFERROR(VLOOKUP(AI27,Довідник_мінералів!$A:$B,2,0),0)*AJ27/100,0))) | AL27: 3 | AM27: сульфат заліза(II) | AQ27: =IF(AL27="","",IF(AN27="",IFERROR(VLOOKUP(AM27,Довідник_мінералів!$A:$B,2,0),"-"),ROUND(IFERROR(VLOOKUP(AM27,Довідник_мінералів!$A:$B,2,0),0)*AN27/100+IFERROR(VLOOKUP(AO27,Довідник_мінералів!$A:$B,2,0),0)*AP27/100,0))) | AR27: 2 | AS27: сульфат міді | AU27: =IF(AR27="","",IFERROR(VLOOKUP(AS27,Довідник_мінералів!$A:$B,2,0),"-")) | AV27: 1 | AW27: оксид марганцю | AY27: =IF(AV27="","",IFERROR(VLOOKUP(AW27,Довідник_мінералів!$A:$B,2,0),"-")) | BB27: =IF(SE27="","",IFERROR(VLOOKUP(BA27,Довідник_мінералів!$A:$B,2,0),"-")) | BC27: 0.25 | BD27: Ca 0.22%; P 0.19%; Na 0.3%; Mg 0.012%; таурин 0.1%; підкислювачі: Ca сульфат 0.25%, DL-метіонін 0.03%
A28: rc_renal_dry_cat | B28: Royal Canin | C28: Renal | D28: Renal Feline (сухий) | E28: сухий | F28: кіт | G28: ХХН нирки | I28: https://www.royalcanin.com/ua/cats/products/vet-products/renal-3900 | J28: 23 | K28: 17 | L28: 4.6 | M28: 5.9 | O28: =IF(J28="","",ROUND(J28/(1-N28/100),1)) | P28: =IF(K28="","",ROUND(K28/(1-N28/100),1)) | Q28: =IF(L28="","",ROUND(L28/(1-N28/100),1)) | R28: =IF(M28="","",ROUND(M28/(1-N28/100),1)) | S28: Кукурудзяне борошно, рис, дегідратовані протеїни свинини (L.I.P.), тваринні жири, кукурудзяний глютен, рослинна клітковина, кукурудза, гідролізат протеїнів тваринного походження, мінеральні речовини, пшеничний глютен (L.I.P.), жом цикорію, риб'ячий жир, соєва олія | T28: дегідратовані протеїни свинини (L.I.P.) | U28: кукурудзяний глютен | V28: пшеничний глютен (L.I.P.) | X28: 800 | AG28: не вказано у UA маркуванні | AK28: =IF(AF28="","",IF(AH28="",IFERROR(VLOOKUP(AG28,Довідник_мінералів!$A:$B,2,0),"-"),ROUND(IFERROR(VLOOKUP(AG28,Довідник_мінералів!$A:$B,2,0),0)*AH28/100+IFERROR(VLOOKUP(AI28,Довідник_мінералів!$A:$B,2,0),0)*AJ28/100,0))) | AM28: не вказано у UA маркуванні | AQ28: =IF(AL28="","",IF(AN28="",IFERROR(VLOOKUP(AM28,Довідник_мінералів!$A:$B,2,0),"-"),ROUND(IFERROR(VLOOKUP(AM28,Довідник_мінералів!$A:$B,2,0),0)*AN28/100+IFERROR(VLOOKUP(AO28,Довідник_мінералів!$A:$B,2,0),0)*AP28/100,0))) | AS28: сульфат міді (знижений рівень) | AU28: =IF(AR28="","",IFERROR(VLOOKUP(AS28,Довідник_мінералів!$A:$B,2,0),"-")) | AY28: =IF(AV28="","",IFERROR(VLOOKUP(AW28,Довідник_мінералів!$A:$B,2,0),"-")) | BB28: =IF(SE28="","",IFERROR(VLOOKUP(BA28,Довідник_мінералів!$A:$B,2,0),"-")) | BD28: Ca 0.6%; P 0.3%; K 0.9%; Na 0.4%; Mg 0.07%; EPA/DHA 0.42%; підлужувачі: цитрат калію, карбонат кальцію; НИЗЬКИЙ фосфор
A29: rc_renal_select_dry_cat | B29: Royal Canin | C29: Renal | D29: Renal Select (сухий) | E29: сухий | F29: кіт | G29: ХХН нирки вибагливі коти | I29: https://www.royalcanin.com/ua/cats/products/vet-products/renal-select-feline-dry-dry | J29: 24.5 | K29: 21.5 | L29: 4.6 | M29: 6.6 | O29: =IF(J29="","",ROUND(J29/(1-N29/100),1)) | P29: =IF(K29="","",ROUND(K29/(1-N29/100),1)) | Q29: =IF(L29="","",ROUND(L29/(1-N29/100),1)) | R29: =IF(M29="","",ROUND(M29/(1-N29/100),1)) | S29: Тваринні жири, рис, оброблене пшеничне борошно, дегідратовані протеїни свинини (L.I.P.), пшеничне борошно, пшеничний глютен (L.I.P.), рослинна клітковина, кукурудзяний глютен, гідролізат білків тваринного походження, дегідрована риба, мінеральні речовини, екстракт цикорію, риб'ячий жир, соєва олія | T29: тваринні жири | U29: дегідратовані протеїни свинини (L.I.P.) | V29: пшеничний глютен (L.I.P.) | W29: 21000 | X29: 800 | AF29: 148 | AG29: оксид цинку / сульфат цинку | AK29: =IF(AF29="","",IF(AH29="",IFERROR(VLOOKUP(AG29,Довідник_мінералів!$A:$B,2,0),"-"),ROUND(IFERROR(VLOOKUP(AG29,Довідник_мінералів!$A:$B,2,0),0)*AH29/100+IFERROR(VLOOKUP(AI29,Довідник_мінералів!$A:$B,2,0),0)*AJ29/100,0))) | AL29: 45 | AM29: сульфат заліза(II) | AQ29: =IF(AL29="","",IF(AN29="",IFERROR(VLOOKUP(AM29,Довідник_мінералів!$A:$B,2,0),"-"),ROUND(IFERROR(VLOOKUP(AM29,Довідник_мінералів!$A:$B,2,0),0)*AN29/100+IFERROR(VLOOKUP(AO29,Довідник_мінералів!$A:$B,2,0),0)*AP29/100,0))) | AR29: 14 | AS29: сульфат міді | AU29: =IF(AR29="","",IFERROR(VLOOKUP(AS29,Довідник_мінералів!$A:$B,2,0),"-")) | AV29: 58 | AW29: оксид марганцю | AY29: =IF(AV29="","",IFERROR(VLOOKUP(AW29,Довідник_мінералів!$A:$B,2,0),"-")) | AZ29: 0.08 | BA29: селеніт натрію | BB29: =IF(SE29="","",IFERROR(VLOOKUP(BA29,Довідник_мінералів!$A:$B,2,0),"-")) | BC29: 4.5 | BD29: Ca 0.7%; P 0.41%; K 0.9%; Na 0.45%; Mg 0.08%; EPA/DHA 0.41%; підлужувачі: цитрат калію, карбонат кальцію
A30: rc_renal_fish_wet_cat | B30: Royal Canin | C30: Renal | D30: Renal Feline Fish (вологий) | E30: вологий | F30: кіт | G30: ХХН нирки | I30: https://www.royalcanin.com/ua/cats/products/vet-products/renal-fish-wet | J30: 6.6 | K30: 6 | L30: 1 | M30: 1.1 | N30: 80 | O30: =IF(J30="","",ROUND(J30/(1-N30/100),1)) | P30: =IF(K30="","",ROUND(K30/(1-N30/100),1)) | Q30: =IF(L30="","",ROUND(L30/(1-N30/100),1)) | R30: =IF(M30="","",ROUND(M30/(1-N30/100),1)) | S30: М'ясо та м'ясні субпродукти, риба та рибні субпродукти, злакові, олії та жири, мінеральні речовини | T30: риба та рибні субпродукти | U30: м'ясо та м'ясні субпродукти | V30: злакові | X30: 330 | AK30: =IF(AF30="","",IF(AH30="",IFERROR(VLOOKUP(AG30,Довідник_мінералів!$A:$B,2,0),"-"),ROUND(IFERROR(VLOOKUP(AG30,Довідник_мінералів!$A:$B,2,0),0)*AH30/100+IFERROR(VLOOKUP(AI30,Довідник_мінералів!$A:$B,2,0),0)*AJ30/100,0))) | AQ30: =IF(AL30="","",IF(AN30="",IFERROR(VLOOKUP(AM30,Довідник_мінералів!$A:$B,2,0),"-"),ROUND(IFERROR(VLOOKUP(AM30,Довідник_мінералів!$A:$B,2,0),0)*AN30/100+IFERROR(VLOOKUP(AO30,Довідник_мінералів!$A:$B,2,0),0)*AP30/100,0))) | AU30: =IF(AR30="","",IFERROR(VLOOKUP(AS30,Довідник_мінералів!$A:$B,2,0),"-")) | AY30: =IF(AV30="","",IFERROR(VLOOKUP(AW30,Довідник_мінералів!$A:$B,2,0),"-")) | BB30: =IF(SE30="","",IFERROR(VLOOKUP(BA30,Довідник_мінералів!$A:$B,2,0),"-")) | BD30: Ca 0.14%; P 0.09%; K 0.18%; Na 0.08%; Mg 0.016%; підлужувачі: цитрат калію, карбонат кальцію; НИЗЬКИЙ фосфор
A31: rc_renal_beef_wet_cat | B31: Royal Canin | C31: Renal | D31: Renal Feline Beef (вологий) | E31: вологий | F31: кіт | G31: ХХН нирки | I31: https://www.royalcanin.com/ua/cats/products/vet-products/renal-beef-wet | J31: 6.7 | K31: 6.6 | L31: 0.5 | M31: 1.1 | N31: 80 | O31: =IF(J31="","",ROUND(J31/(1-N31/100),1)) | P31: =IF(K31="","",ROUND(K31/(1-N31/100),1)) | Q31: =IF(L31="","",ROUND(L31/(1-N31/100),1)) | R31: =IF(M31="","",ROUND(M31/(1-N31/100),1)) | S31: М'ясо та м'ясні субпродукти (яловичина 4%), злаки, олії та жири, мінеральні речовини, субпродукти рослинного походження, вуглеводи | T31: яловичина (4%) | U31: м'ясо та м'ясні субпродукти | V31: злаки | X31: 420 | AK31: =IF(AF31="","",IF(AH31="",IFERROR(VLOOKUP(AG31,Довідник_мінералів!$A:$B,2,0),"-"),ROUND(IFERROR(VLOOKUP(AG31,Довідник_мінералів!$A:$B,2,0),0)*AH31/100+IFERROR(VLOOKUP(AI31,Довідник_мінералів!$A:$B,2,0),0)*AJ31/100,0))) | AQ31: =IF(AL31="","",IF(AN31="",IFERROR(VLOOKUP(AM31,Довідник_мінералів!$A:$B,2,0),"-"),ROUND(IFERROR(VLOOKUP(AM31,Довідник_мінералів!$A:$B,2,0),0)*AN31/100+IFERROR(VLOOKUP(AO31,Довідник_мінералів!$A:$B,2,0),0)*AP31/100,0))) | AU31: =IF(AR31="","",IFERROR(VLOOKUP(AS31,Довідник_мінералів!$A:$B,2,0),"-")) | AY31: =IF(AV31="","",IFERROR(VLOOKUP(AW31,Довідник_мінералів!$A:$B,2,0),"-")) | BB31: =IF(SE31="","",IFERROR(VLOOKUP(BA31,Довідник_мінералів!$A:$B,2,0),"-")) | BD31: Ca 0.13%; P 0.075%; K 0.19%; Na 0.08%; Mg 0.016%; підлужувачі: цитрат калію, карбонат кальцію
A32: rc_hepatic_dry_cat | B32: Royal Canin | C32: Hepatic | D32: Hepatic (сухий) | E32: сухий | F32: кіт | G32: захворювання печінки | I32: https://www.royalcanin.com/ua/cats/products/vet-products/hepatic-4012 | J32: 26 | K32: 22 | L32: 5.1 | M32: 6.2 | O32: =IF(J32="","",ROUND(J32/(1-N32/100),1)) | P32: =IF(K32="","",ROUND(K32/(1-N32/100),1)) | Q32: =IF(L32="","",ROUND(L32/(1-N32/100),1)) | R32: =IF(M32="","",ROUND(M32/(1-N32/100),1)) | S32: Рис, тваринні жири, кукурудза, пшеничний глютен, дегідратовані протеїни свинини, кукурудзяний глютен, рослинна клітковина, гідролізована печінка свійської птиці, мінеральні речовини, екстракт цикорію, риб'ячий жир, соєва олія, фруктоолігосахариди, гідролізат дріжджів (МОС) | T32: рис | U32: дегідратовані протеїни свинини | V32: гідролізована печінка свійської птиці | AK32: =IF(AF32="","",IF(AH32="",IFERROR(VLOOKUP(AG32,Довідник_мінералів!$A:$B,2,0),"-"),ROUND(IFERROR(VLOOKUP(AG32,Довідник_мінералів!$A:$B,2,0),0)*AH32/100+IFERROR(VLOOKUP(AI32,Довідник_мінералів!$A:$B,2,0),0)*AJ32/100,0))) | AQ32: =IF(AL32="","",IF(AN32="",IFERROR(VLOOKUP(AM32,Довідник_мінералів!$A:$B,2,0),"-"),ROUND(IFERROR(VLOOKUP(AM32,Довідник_мінералів!$A:$B,2,0),0)*AN32/100+IFERROR(VLOOKUP(AO32,Довідник_мінералів!$A:$B,2,0),0)*AP32/100,0))) | AS32: мідь знижена (загальна Cu 3.6 мг/кг) | AU32: =IF(AR32="","",IFERROR(VLOOKUP(AS32,Довідник_мінералів!$A:$B,2,0),"-")) | AY32: =IF(AV32="","",IFERROR(VLOOKUP(AW32,Довідник_мінералів!$A:$B,2,0),"-")) | BB32: =IF(SE32="","",IFERROR(VLOOKUP(BA32,Довідник_мінералів!$A:$B,2,0),"-")) | BD32: Na 0.3%; Cu загальна 3.6 мг/кг (ЗНИЖЕНА); EPA/DHA 0.35%; S/O index
A33: rc_hypoallergenic_dry_cat | B33: Royal Canin | C33: Hypoallergenic | D33: Hypoallergenic (сухий) | E33: сухий | F33: кіт | G33: алергія / IBD / EPI | I33: https://www.royalcanin.com/ua/cats/products/vet-products/hypoallergenic-3902 | J33: 25.5 | K33: 20 | L33: 3.6 | M33: 6.3 | O33: =IF(J33="","",ROUND(J33/(1-N33/100),1)) | P33: =IF(K33="","",ROUND(K33/(1-N33/100),1)) | Q33: =IF(L33="","",ROUND(L33/(1-N33/100),1)) | R33: =IF(M33="","",ROUND(M33/(1-N33/100),1)) | S33: Рис, гідролізат ізолята соєвого протеїну, тваринні жири, рослинна клітковина, мінеральні речовини, буряковий жом, гідролізована печінка свійської птиці, соєва олія, риб'ячий жир, фруктоолігосахариди, олія огірочника (GLA), екстракт чорнобривців (лютеїн) | T33: гідролізат ізолята соєвого протеїну | U33: рис | V33: гідролізована печінка свійської птиці | W33: 27000 | X33: 800 | AF33: 153 | AG33: оксид цинку / сульфат цинку | AK33: =IF(AF33="","",IF(AH33="",IFERROR(VLOOKUP(AG33,Довідник_мінералів!$A:$B,2,0),"-"),ROUND(IFERROR(VLOOKUP(AG33,Довідник_мінералів!$A:$B,2,0),0)*AH33/100+IFERROR(VLOOKUP(AI33,Довідник_мінералів!$A:$B,2,0),0)*AJ33/100,0))) | AL33: 41 | AM33: сульфат заліза(II) | AQ33: =IF(AL33="","",IF(AN33="",IFERROR(VLOOKUP(AM33,Довідник_мінералів!$A:$B,2,0),"-"),ROUND(IFERROR(VLOOKUP(AM33,Довідник_мінералів!$A:$B,2,0),0)*AN33/100+IFERROR(VLOOKUP(AO33,Довідник_мінералів!$A:$B,2,0),0)*AP33/100,0))) | AR33: 15 | AS33: сульфат міді | AU33: =IF(AR33="","",IFERROR(VLOOKUP(AS33,Довідник_мінералів!$A:$B,2,0),"-")) | AV33: 54 | AW33: оксид марганцю | AY33: =IF(AV33="","",IFERROR(VLOOKUP(AW33,Довідник_мінералів!$A:$B,2,0),"-")) | AZ33: 0.26 | BA33: селеніт натрію | BB33: =IF(SE33="","",IFERROR(VLOOKUP(BA33,Довідник_мінералів!$A:$B,2,0),"-")) | BC33: 3.7 | BD33: EPA/DHA 3.2 г/кг; Омега-3 9.8 г/кг; лінолева+арахідонова 46.4 г/кг; олія огірочника (GLA)
A34: rc_anallergenic_dry_cat | B34: Royal Canin | C34: Anallergenic | D34: Anallergenic (сухий) | E34: сухий | F34: кіт | G34: важка алергія / елімінаційна дієта | I34: https://www.royalcanin.com/ua/cats/products/vet-products/anallergenic-dry | J34: 24.6 | K34: 17 | L34: 3.7 | M34: 7.6 | O34: =IF(J34="","",ROUND(J34/(1-N34/100),1)) | P34: =IF(K34="","",ROUND(K34/(1-N34/100),1)) | Q34: =IF(L34="","",ROUND(L34/(1-N34/100),1)) | R34: =IF(M34="","",ROUND(M34/(1-N34/100),1)) | S34: Кукурудзяний крохмаль, пір'євий гідролізат малої молекулярної ваги (L-амінокислоти та олігопептиди), кокосова олія, соєва олія, рослинна клітковина, мінеральні речовини, тваринний жир, риб'ячий жир, екстракт цикорію, фруктоолігосахариди, мальтодекстрин | T34: пір'євий гідролізат малої молекулярної ваги | U34: кукурудзяний крохмаль | V34: кокосова олія | W34: 36500 | X34: 800 | AF34: 162 | AG34: оксид цинку / сульфат цинку | AK34: =IF(AF34="","",IF(AH34="",IFERROR(VLOOKUP(AG34,Довідник_мінералів!$A:$B,2,0),"-"),ROUND(IFERROR(VLOOKUP(AG34,Довідник_мінералів!$A:$B,2,0),0)*AH34/100+IFERROR(VLOOKUP(AI34,Довідник_мінералів!$A:$B,2,0),0)*AJ34/100,0))) | AL34: 42 | AM34: сульфат заліза(II) | AQ34: =IF(AL34="","",IF(AN34="",IFERROR(VLOOKUP(AM34,Довідник_мінералів!$A:$B,2,0),"-"),ROUND(IFERROR(VLOOKUP(AM34,Довідник_мінералів!$A:$B,2,0),0)*AN34/100+IFERROR(VLOOKUP(AO34,Довідник_мінералів!$A:$B,2,0),0)*AP34/100,0))) | AR34: 15 | AS34: сульфат міді | AU34: =IF(AR34="","",IFERROR(VLOOKUP(AS34,Довідник_мінералів!$A:$B,2,0),"-")) | AV34: 55 | AW34: оксид марганцю | AY34: =IF(AV34="","",IFERROR(VLOOKUP(AW34,Довідник_мінералів!$A:$B,2,0),"-")) | AZ34: 0.26 | BA34: селеніт натрію | BB34: =IF(SE34="","",IFERROR(VLOOKUP(BA34,Довідник_мінералів!$A:$B,2,0),"-")) | BC34: 3.8 | BD34: Єдиний джерело білку: пір'євий гідролізат (не містить жодного цільного білка); лінолева+арахідонова 33.9 г/кг
A35: rc_diabetic_dry_cat | B35: Royal Canin | C35: Diabetic | D35: Diabetic (сухий) | E35: сухий | F35: кіт | G35: цукровий діабет | I35: https://www.royalcanin.com/ua/cats/products/vet-products/diabetic-feline-dry | J35: 46 | K35: 12 | L35: 3.8 | M35: 6.4 | O35: =IF(J35="","",ROUND(J35/(1-N35/100),1)) | P35: =IF(K35="","",ROUND(K35/(1-N35/100),1)) | Q35: =IF(L35="","",ROUND(L35/(1-N35/100),1)) | R35: =IF(M35="","",ROUND(M35/(1-N35/100),1)) | S35: Дегідратовані протеїни м'яса птиці, ячмінь, пшеничний глютен (L.I.P.), кукурудзяний глютен, ізолят соєвого протеїну (L.I.P.), тапіока, тваринні жири, гідролізат білків тваринного походження, рослинна клітковина, екстракт цикорію, мінеральні речовини, риб'ячий жир, оболонка та насіння подорожника, фруктоолігосахариди, соєва олія | T35: дегідратовані протеїни м'яса птиці | U35: ячмінь | V35: ізолят соєвого протеїну (L.I.P.) | W35: 25000 | X35: 1000 | AF35: 130 | AG35: оксид цинку / сульфат цинку | AK35: =IF(AF35="","",IF(AH35="",IFERROR(VLOOKUP(AG35,Довідник_мінералів!$A:$B,2,0),"-"),ROUND(IFERROR(VLOOKUP(AG35,Довідник_мінералів!$A:$B,2,0),0)*AH35/100+IFERROR(VLOOKUP(AI35,Довідник_мінералів!$A:$B,2,0),0)*AJ35/100,0))) | AL35: 33 | AM35: сульфат заліза(II) | AQ35: =IF(AL35="","",IF(AN35="",IFERROR(VLOOKUP(AM35,Довідник_мінералів!$A:$B,2,0),"-"),ROUND(IFERROR(VLOOKUP(AM35,Довідник_мінералів!$A:$B,2,0),0)*AN35/100+IFERROR(VLOOKUP(AO35,Довідник_мінералів!$A:$B,2,0),0)*AP35/100,0))) | AR35: 10 | AS35: сульфат міді | AU35: =IF(AR35="","",IFERROR(VLOOKUP(AS35,Довідник_мінералів!$A:$B,2,0),"-")) | AV35: 43 | AW35: оксид марганцю | AY35: =IF(AV35="","",IFERROR(VLOOKUP(AW35,Довідник_мінералів!$A:$B,2,0),"-")) | AZ35: 0.05 | BA35: селеніт натрію | BB35: =IF(SE35="","",IFERROR(VLOOKUP(BA35,Довідник_мінералів!$A:$B,2,0),"-")) | BC35: 3.3 | BD35: ДУЖЕ ВИСОКИЙ білок 46%; крохмаль 19%; цукри 1.5%; ячмінь + тапіока як джерела вуглеводів (низький ГІ)
